The token has not been saved to the git credentials helper. Pass `add_to_git_credential=True` in this function directly or `--add-to-git-credential` if using via `huggingface-cli` if you want to set the git credential as well.
Token is valid (permission: fineGrained).
Your token has been saved to /filer/tmp1/hz624/.cache/huggingface/hub/token
Login successful
Attack started at: 2024-08-30 10:49
Namespace(llm_name='gpt-4o-mini', max_gpu_memory=None, eval_device=None, max_new_tokens=256, scheduler_log_mode='console', agent_log_mode='console', llm_kernel_log_mode='console', use_backend='None', workflow_mode='automatic', attacker_tools_path='data/all_attack_tools_aggressive.jsonl', tasks_path='data/cot_data/agent_task_cot.jsonl', tools_info_path='data/all_normal_tools.jsonl', observation_prompt_injection=False, plan_attack=False, action_attack=False, direct_prompt_injection=False, jailbreak=False, attack_type='naive', cot_backdoor=True, cot_clean=False, target='ResearcherProfileManager', trigger='@_@', memory_attack=False, clean=False, result_file='logs/cot_backdoor/gpt-4o-mini/result_statistics.log', database='memory_db/chroma_db', task_num=4)
[ðŸ¤–gpt-4o-mini] AIOS LLM successfully loaded.

Traceback (most recent call last):
  File "/common/users/hz624/AgentAttackBench/main_attacker.py", line 306, in <module>
    main()
  File "/common/users/hz624/AgentAttackBench/main_attacker.py", line 166, in main
    tasks_path = pd.read_json(args.tasks_path, lines=True)
                 ^^^^^^^^^^^^^^^^^^^^^^^^^^^^^^^^^^^^^^^^^
  File "/common/home/hz624/anaconda3/envs/AIOS/lib/python3.11/site-packages/pandas/io/json/_json.py", line 815, in read_json
    return json_reader.read()
           ^^^^^^^^^^^^^^^^^^
  File "/common/home/hz624/anaconda3/envs/AIOS/lib/python3.11/site-packages/pandas/io/json/_json.py", line 1023, in read
    obj = self._get_object_parser(self._combine_lines(data_lines))
          ^^^^^^^^^^^^^^^^^^^^^^^^^^^^^^^^^^^^^^^^^^^^^^^^^^^^^^^^
  File "/common/home/hz624/anaconda3/envs/AIOS/lib/python3.11/site-packages/pandas/io/json/_json.py", line 1051, in _get_object_parser
    obj = FrameParser(json, **kwargs).parse()
          ^^^^^^^^^^^^^^^^^^^^^^^^^^^^^^^^^^^
  File "/common/home/hz624/anaconda3/envs/AIOS/lib/python3.11/site-packages/pandas/io/json/_json.py", line 1187, in parse
    self._parse()
  File "/common/home/hz624/anaconda3/envs/AIOS/lib/python3.11/site-packages/pandas/io/json/_json.py", line 1403, in _parse
    ujson_loads(json, precise_float=self.precise_float), dtype=None
    ^^^^^^^^^^^^^^^^^^^^^^^^^^^^^^^^^^^^^^^^^^^^^^^^^^^
ValueError: Expected object or value
