/common/home/hz624/anaconda3/envs/AIOS/lib/python3.11/site-packages/transformers/utils/hub.py:127: FutureWarning: Using `TRANSFORMERS_CACHE` is deprecated and will be removed in v5 of Transformers. Use `HF_HOME` instead.
  warnings.warn(
Attack started at: 2024-07-23 06:56
Namespace(llm_name='meta-llama/Meta-Llama-3-8B-Instruct', max_gpu_memory={'0': '24GB', '1': '24GB', '2': '24GB', '3': '24GB', '4': '24GB', '5': '24GB', '6': '24GB'}, eval_device='cuda:7', max_new_tokens=256, scheduler_log_mode='console', agent_log_mode='console', llm_kernel_log_mode='console', use_backend=None, workflow_mode='manual', attacker_tools_path='data/test.jsonl', tasks_path='data/agent_tasks/example/academic_agent_task_test.txt', agent_path='example/academic_agent_attack', observation_prompt_injection=True, plan_attack=False, action_attack=False, direct_prompt_injection=False, attack_type='naive', cot_backdoor=False)
Traceback (most recent call last):
  File "/common/home/hz624/anaconda3/envs/AIOS/lib/python3.11/site-packages/huggingface_hub/utils/_errors.py", line 304, in hf_raise_for_status
    response.raise_for_status()
  File "/common/home/hz624/anaconda3/envs/AIOS/lib/python3.11/site-packages/requests/models.py", line 1024, in raise_for_status
    raise HTTPError(http_error_msg, response=self)
requests.exceptions.HTTPError: 403 Client Error: Forbidden for url: https://huggingface.co/meta-llama/Meta-Llama-3-8B-Instruct/resolve/main/config.json

The above exception was the direct cause of the following exception:

Traceback (most recent call last):
  File "/common/home/hz624/anaconda3/envs/AIOS/lib/python3.11/site-packages/transformers/utils/hub.py", line 402, in cached_file
    resolved_file = hf_hub_download(
                    ^^^^^^^^^^^^^^^^
  File "/common/home/hz624/anaconda3/envs/AIOS/lib/python3.11/site-packages/huggingface_hub/utils/_validators.py", line 114, in _inner_fn
    return fn(*args, **kwargs)
           ^^^^^^^^^^^^^^^^^^^
  File "/common/home/hz624/anaconda3/envs/AIOS/lib/python3.11/site-packages/huggingface_hub/file_download.py", line 1221, in hf_hub_download
    return _hf_hub_download_to_cache_dir(
           ^^^^^^^^^^^^^^^^^^^^^^^^^^^^^^
  File "/common/home/hz624/anaconda3/envs/AIOS/lib/python3.11/site-packages/huggingface_hub/file_download.py", line 1325, in _hf_hub_download_to_cache_dir
    _raise_on_head_call_error(head_call_error, force_download, local_files_only)
  File "/common/home/hz624/anaconda3/envs/AIOS/lib/python3.11/site-packages/huggingface_hub/file_download.py", line 1823, in _raise_on_head_call_error
    raise head_call_error
  File "/common/home/hz624/anaconda3/envs/AIOS/lib/python3.11/site-packages/huggingface_hub/file_download.py", line 1722, in _get_metadata_or_catch_error
    metadata = get_hf_file_metadata(url=url, proxies=proxies, timeout=etag_timeout, headers=headers)
               ^^^^^^^^^^^^^^^^^^^^^^^^^^^^^^^^^^^^^^^^^^^^^^^^^^^^^^^^^^^^^^^^^^^^^^^^^^^^^^^^^^^^^
  File "/common/home/hz624/anaconda3/envs/AIOS/lib/python3.11/site-packages/huggingface_hub/utils/_validators.py", line 114, in _inner_fn
    return fn(*args, **kwargs)
           ^^^^^^^^^^^^^^^^^^^
  File "/common/home/hz624/anaconda3/envs/AIOS/lib/python3.11/site-packages/huggingface_hub/file_download.py", line 1645, in get_hf_file_metadata
    r = _request_wrapper(
        ^^^^^^^^^^^^^^^^^
  File "/common/home/hz624/anaconda3/envs/AIOS/lib/python3.11/site-packages/huggingface_hub/file_download.py", line 372, in _request_wrapper
    response = _request_wrapper(
               ^^^^^^^^^^^^^^^^^
  File "/common/home/hz624/anaconda3/envs/AIOS/lib/python3.11/site-packages/huggingface_hub/file_download.py", line 396, in _request_wrapper
    hf_raise_for_status(response)
  File "/common/home/hz624/anaconda3/envs/AIOS/lib/python3.11/site-packages/huggingface_hub/utils/_errors.py", line 321, in hf_raise_for_status
    raise GatedRepoError(message, response) from e
huggingface_hub.utils._errors.GatedRepoError: 403 Client Error. (Request ID: Root=1-669f8c60-634499db58f335310c3ff019;80fd581e-0950-41b2-bf90-c8c08c0778ab)

Cannot access gated repo for url https://huggingface.co/meta-llama/Meta-Llama-3-8B-Instruct/resolve/main/config.json.
Your request to access model meta-llama/Meta-Llama-3-8B-Instruct has been rejected by the repo's authors.

The above exception was the direct cause of the following exception:

Traceback (most recent call last):
  File "/common/users/hz624/AgentAttackBench/main_attacker.py", line 162, in <module>
    main()
  File "/common/users/hz624/AgentAttackBench/main_attacker.py", line 75, in main
    llm = llms.LLMKernel(
          ^^^^^^^^^^^^^^^
  File "/common/users/hz624/AgentAttackBench/aios/llm_core/llms.py", line 48, in __init__
    self.model = HfNativeLLM(
                 ^^^^^^^^^^^^
  File "/common/users/hz624/AgentAttackBench/aios/llm_core/llm_classes/base_llm.py", line 33, in __init__
    self.load_llm_and_tokenizer()
  File "/common/users/hz624/AgentAttackBench/aios/llm_core/llm_classes/hf_native_llm.py", line 24, in load_llm_and_tokenizer
    self.model = MODEL_CLASS[self.model_type].from_pretrained(
                 ^^^^^^^^^^^^^^^^^^^^^^^^^^^^^^^^^^^^^^^^^^^^^
  File "/common/home/hz624/anaconda3/envs/AIOS/lib/python3.11/site-packages/transformers/models/auto/auto_factory.py", line 524, in from_pretrained
    config, kwargs = AutoConfig.from_pretrained(
                     ^^^^^^^^^^^^^^^^^^^^^^^^^^^
  File "/common/home/hz624/anaconda3/envs/AIOS/lib/python3.11/site-packages/transformers/models/auto/configuration_auto.py", line 965, in from_pretrained
    config_dict, unused_kwargs = PretrainedConfig.get_config_dict(pretrained_model_name_or_path, **kwargs)
                                 ^^^^^^^^^^^^^^^^^^^^^^^^^^^^^^^^^^^^^^^^^^^^^^^^^^^^^^^^^^^^^^^^^^^^^^^^^
  File "/common/home/hz624/anaconda3/envs/AIOS/lib/python3.11/site-packages/transformers/configuration_utils.py", line 632, in get_config_dict
    config_dict, kwargs = cls._get_config_dict(pretrained_model_name_or_path, **kwargs)
                          ^^^^^^^^^^^^^^^^^^^^^^^^^^^^^^^^^^^^^^^^^^^^^^^^^^^^^^^^^^^^^
  File "/common/home/hz624/anaconda3/envs/AIOS/lib/python3.11/site-packages/transformers/configuration_utils.py", line 689, in _get_config_dict
    resolved_config_file = cached_file(
                           ^^^^^^^^^^^^
  File "/common/home/hz624/anaconda3/envs/AIOS/lib/python3.11/site-packages/transformers/utils/hub.py", line 420, in cached_file
    raise EnvironmentError(
OSError: You are trying to access a gated repo.
Make sure to have access to it at https://huggingface.co/meta-llama/Meta-Llama-3-8B-Instruct.
403 Client Error. (Request ID: Root=1-669f8c60-634499db58f335310c3ff019;80fd581e-0950-41b2-bf90-c8c08c0778ab)

Cannot access gated repo for url https://huggingface.co/meta-llama/Meta-Llama-3-8B-Instruct/resolve/main/config.json.
Your request to access model meta-llama/Meta-Llama-3-8B-Instruct has been rejected by the repo's authors.
