Attack started at: 2024-07-31 12:10
Namespace(llm_name='mistralai/Mixtral-8x7B-v0.2', max_gpu_memory={'0': '24GB', '1': '24GB', '2': '24GB', '3': '24GB', '4': '24GB', '5': '24GB', '6': '24GB'}, eval_device='cuda:7', max_new_tokens=1024, scheduler_log_mode='console', agent_log_mode='console', llm_kernel_log_mode='console', use_backend='vllm', workflow_mode='automatic', attacker_tools_path='data/all_attacker_tools_non_aggressive.jsonl', tasks_path='data/agent_task.jsonl', tools_info_path='data/all_normal_tools.jsonl', observation_prompt_injection=False, plan_attack=False, action_attack=False, direct_prompt_injection=True, attack_type='naive', cot_backdoor=False)
Traceback (most recent call last):
  File "/common/home/hz624/anaconda3/envs/AIOS/lib/python3.11/site-packages/huggingface_hub/utils/_errors.py", line 304, in hf_raise_for_status
    response.raise_for_status()
  File "/common/home/hz624/anaconda3/envs/AIOS/lib/python3.11/site-packages/requests/models.py", line 1024, in raise_for_status
    raise HTTPError(http_error_msg, response=self)
requests.exceptions.HTTPError: 404 Client Error: Not Found for url: https://huggingface.co/mistralai/Mixtral-8x7B-v0.2/resolve/main/config.json

The above exception was the direct cause of the following exception:

Traceback (most recent call last):
  File "/common/home/hz624/anaconda3/envs/AIOS/lib/python3.11/site-packages/transformers/utils/hub.py", line 402, in cached_file
    resolved_file = hf_hub_download(
                    ^^^^^^^^^^^^^^^^
  File "/common/home/hz624/anaconda3/envs/AIOS/lib/python3.11/site-packages/huggingface_hub/utils/_validators.py", line 114, in _inner_fn
    return fn(*args, **kwargs)
           ^^^^^^^^^^^^^^^^^^^
  File "/common/home/hz624/anaconda3/envs/AIOS/lib/python3.11/site-packages/huggingface_hub/file_download.py", line 1221, in hf_hub_download
    return _hf_hub_download_to_cache_dir(
           ^^^^^^^^^^^^^^^^^^^^^^^^^^^^^^
  File "/common/home/hz624/anaconda3/envs/AIOS/lib/python3.11/site-packages/huggingface_hub/file_download.py", line 1325, in _hf_hub_download_to_cache_dir
    _raise_on_head_call_error(head_call_error, force_download, local_files_only)
  File "/common/home/hz624/anaconda3/envs/AIOS/lib/python3.11/site-packages/huggingface_hub/file_download.py", line 1823, in _raise_on_head_call_error
    raise head_call_error
  File "/common/home/hz624/anaconda3/envs/AIOS/lib/python3.11/site-packages/huggingface_hub/file_download.py", line 1722, in _get_metadata_or_catch_error
    metadata = get_hf_file_metadata(url=url, proxies=proxies, timeout=etag_timeout, headers=headers)
               ^^^^^^^^^^^^^^^^^^^^^^^^^^^^^^^^^^^^^^^^^^^^^^^^^^^^^^^^^^^^^^^^^^^^^^^^^^^^^^^^^^^^^
  File "/common/home/hz624/anaconda3/envs/AIOS/lib/python3.11/site-packages/huggingface_hub/utils/_validators.py", line 114, in _inner_fn
    return fn(*args, **kwargs)
           ^^^^^^^^^^^^^^^^^^^
  File "/common/home/hz624/anaconda3/envs/AIOS/lib/python3.11/site-packages/huggingface_hub/file_download.py", line 1645, in get_hf_file_metadata
    r = _request_wrapper(
        ^^^^^^^^^^^^^^^^^
  File "/common/home/hz624/anaconda3/envs/AIOS/lib/python3.11/site-packages/huggingface_hub/file_download.py", line 372, in _request_wrapper
    response = _request_wrapper(
               ^^^^^^^^^^^^^^^^^
  File "/common/home/hz624/anaconda3/envs/AIOS/lib/python3.11/site-packages/huggingface_hub/file_download.py", line 396, in _request_wrapper
    hf_raise_for_status(response)
  File "/common/home/hz624/anaconda3/envs/AIOS/lib/python3.11/site-packages/huggingface_hub/utils/_errors.py", line 352, in hf_raise_for_status
    raise RepositoryNotFoundError(message, response) from e
huggingface_hub.utils._errors.RepositoryNotFoundError: 404 Client Error. (Request ID: Root=1-66aa61f3-6f6eb4b1038b315703dc8d05;6b66e559-63da-4784-a65f-f6dad3447c95)

Repository Not Found for url: https://huggingface.co/mistralai/Mixtral-8x7B-v0.2/resolve/main/config.json.
Please make sure you specified the correct `repo_id` and `repo_type`.
If you are trying to access a private or gated repo, make sure you are authenticated.

The above exception was the direct cause of the following exception:

Traceback (most recent call last):
  File "/common/users/hz624/AgentAttackBench/main_attacker.py", line 184, in <module>
    main()
  File "/common/users/hz624/AgentAttackBench/main_attacker.py", line 85, in main
    llm = llms.LLMKernel(
          ^^^^^^^^^^^^^^^
  File "/common/users/hz624/AgentAttackBench/aios/llm_core/llms.py", line 40, in __init__
    self.model = vLLM(
                 ^^^^^
  File "/common/users/hz624/AgentAttackBench/aios/llm_core/llm_classes/vllm.py", line 19, in __init__
    super().__init__(llm_name,
  File "/common/users/hz624/AgentAttackBench/aios/llm_core/llm_classes/base_llm.py", line 33, in __init__
    self.load_llm_and_tokenizer()
  File "/common/users/hz624/AgentAttackBench/aios/llm_core/llm_classes/vllm.py", line 38, in load_llm_and_tokenizer
    self.model = vllm.LLM(
                 ^^^^^^^^^
  File "/common/home/hz624/anaconda3/envs/AIOS/lib/python3.11/site-packages/vllm/entrypoints/llm.py", line 144, in __init__
    self.llm_engine = LLMEngine.from_engine_args(
                      ^^^^^^^^^^^^^^^^^^^^^^^^^^^
  File "/common/home/hz624/anaconda3/envs/AIOS/lib/python3.11/site-packages/vllm/engine/llm_engine.py", line 336, in from_engine_args
    engine_config = engine_args.create_engine_config()
                    ^^^^^^^^^^^^^^^^^^^^^^^^^^^^^^^^^^
  File "/common/home/hz624/anaconda3/envs/AIOS/lib/python3.11/site-packages/vllm/engine/arg_utils.py", line 630, in create_engine_config
    model_config = ModelConfig(
                   ^^^^^^^^^^^^
  File "/common/home/hz624/anaconda3/envs/AIOS/lib/python3.11/site-packages/vllm/config.py", line 137, in __init__
    self.hf_config = get_config(self.model, trust_remote_code, revision,
                     ^^^^^^^^^^^^^^^^^^^^^^^^^^^^^^^^^^^^^^^^^^^^^^^^^^^
  File "/common/home/hz624/anaconda3/envs/AIOS/lib/python3.11/site-packages/vllm/transformers_utils/config.py", line 33, in get_config
    config = AutoConfig.from_pretrained(
             ^^^^^^^^^^^^^^^^^^^^^^^^^^^
  File "/common/home/hz624/anaconda3/envs/AIOS/lib/python3.11/site-packages/transformers/models/auto/configuration_auto.py", line 965, in from_pretrained
    config_dict, unused_kwargs = PretrainedConfig.get_config_dict(pretrained_model_name_or_path, **kwargs)
                                 ^^^^^^^^^^^^^^^^^^^^^^^^^^^^^^^^^^^^^^^^^^^^^^^^^^^^^^^^^^^^^^^^^^^^^^^^^
  File "/common/home/hz624/anaconda3/envs/AIOS/lib/python3.11/site-packages/transformers/configuration_utils.py", line 632, in get_config_dict
    config_dict, kwargs = cls._get_config_dict(pretrained_model_name_or_path, **kwargs)
                          ^^^^^^^^^^^^^^^^^^^^^^^^^^^^^^^^^^^^^^^^^^^^^^^^^^^^^^^^^^^^^
  File "/common/home/hz624/anaconda3/envs/AIOS/lib/python3.11/site-packages/transformers/configuration_utils.py", line 689, in _get_config_dict
    resolved_config_file = cached_file(
                           ^^^^^^^^^^^^
  File "/common/home/hz624/anaconda3/envs/AIOS/lib/python3.11/site-packages/transformers/utils/hub.py", line 425, in cached_file
    raise EnvironmentError(
OSError: mistralai/Mixtral-8x7B-v0.2 is not a local folder and is not a valid model identifier listed on 'https://huggingface.co/models'
If this is a private repository, make sure to pass a token having permission to this repo either by logging in with `huggingface-cli login` or by passing `token=<your_token>`
